<?xml version="1.0" ?>
<!-- =================================================================================== -->
<!-- |    This document was autogenerated by xacro from quadruped_robot.xacro          | -->
<!-- |    EDITING THIS FILE BY HAND IS NOT RECOMMENDED                                 | -->
<!-- =================================================================================== -->
<robot name="quadruped_robot">
  <!-- =============== Link & Joint =============== -->
  <!-- Base -->
  <link name="robot1_base_footprint"/>
  <joint name="robot1_base_link_joint" type="fixed">
    <origin rpy="0 -1.57079637 0" xyz="0 0 0"/>
    <parent link="robot1_base_footprint"/>
    <child link="robot1_base_link"/>
  </joint>
  <link name="robot1_base_link">
    <visual>
      <geometry>
        <mesh filename="package://robot_description/meshes/DAE/body/body.dae"/>
      </geometry>
    </visual>
    <collision>
      <geometry>
        <mesh filename="package://robot_description/meshes/STL/body/body.stl"/>
      </geometry>
    </collision>
    <inertial>
      <origin xyz="0.01 0.0 0.09"/>
      <mass value="9.5"/>
      <inertia ixx="0.075" ixy="-0.0017" ixz="-0.0017" iyy="0.4" iyz="-0.0008" izz="0.43"/>
    </inertial>
    <surface>
      <friction>
        <ode>
          <mu1>1.2</mu1>
          <mu2>1.2</mu2>
          <kp>1e15</kp>
          <kd>1e13</kd>
        </ode>
      </friction>
      <bounce>
        <restitution_coefficient>0.01</restitution_coefficient>
        <threshold>0</threshold>
      </bounce>
      <contact>
        <ode>
          <max_vel>10</max_vel>
        </ode>
      </contact>
    </surface>
  </link>
  <joint name="robot1_rear_left_leg_joint" type="fixed">
    <origin rpy="0 1.57079637 -1.57079637" xyz="-0.277 0.06 0.089405"/>
    <parent link="robot1_base_link"/>
    <child link="robot1_rear_left_leg_joint_link"/>
    <limit effort="500" lower="-3.14159" upper="3.14159" velocity="10"/>
    <dynamics damping="0.005" friction="0.1"/>
    <axis xyz="0 -1 0"/>
  </joint>
  <link name="robot1_rear_left_leg_joint_link">
    <visual>
      <geometry>
        <mesh filename="package://robot_description/meshes/DAE/leg_joint/leg_joint.dae"/>
      </geometry>
    </visual>
    <collision>
      <geometry>
        <mesh filename="package://robot_description/meshes/STL/leg_joint/leg_joint.stl"/>
      </geometry>
    </collision>
    <inertial>
      <origin xyz="0 0 -0.038"/>
      <mass value="1.16"/>
      <inertia ixx="0.002" ixy="0" ixz="0" iyy="0.002" iyz="0" izz="0.001"/>
    </inertial>
  </link>
  <joint name="robot1_rear_right_leg_joint" type="fixed">
    <origin rpy="0 -1.57079637 -1.57079637" xyz="-0.277 -0.06 0.089405"/>
    <parent link="robot1_base_link"/>
    <child link="robot1_rear_right_leg_joint_link"/>
    <limit effort="500" lower="-3.14159" upper="3.14159" velocity="10"/>
    <dynamics damping="0.005" friction="0.1"/>
    <axis xyz="0 1 0"/>
  </joint>
  <link name="robot1_rear_right_leg_joint_link">
    <visual>
      <geometry>
        <mesh filename="package://robot_description/meshes/DAE/leg_joint/leg_joint.dae"/>
      </geometry>
    </visual>
    <collision>
      <geometry>
        <mesh filename="package://robot_description/meshes/STL/leg_joint/leg_joint.stl"/>
      </geometry>
    </collision>
    <inertial>
      <origin xyz="0 0 -0.038"/>
      <mass value="1.16"/>
      <inertia ixx="0.002" ixy="0" ixz="0" iyy="0.002" iyz="0" izz="0.001"/>
    </inertial>
  </link>
  <joint name="robot1_front_left_leg_joint" type="fixed">
    <origin rpy="0 1.39626344 -1.57079637" xyz="0.282 0.06 0.090255"/>
    <parent link="robot1_base_link"/>
    <child link="robot1_front_left_leg_joint_link"/>
    <limit effort="500" lower="-3.14159" upper="3.14159" velocity="10"/>
    <dynamics damping="0.005" friction="0.1"/>
    <axis xyz="0 -1 0"/>
  </joint>
  <link name="robot1_front_left_leg_joint_link">
    <visual>
      <geometry>
        <mesh filename="package://robot_description/meshes/DAE/leg_joint/leg_joint.dae"/>
      </geometry>
    </visual>
    <collision>
      <geometry>
        <mesh filename="package://robot_description/meshes/STL/leg_joint/leg_joint.stl"/>
      </geometry>
    </collision>
    <inertial>
      <origin xyz="0 0 -0.038"/>
      <mass value="1.16"/>
      <inertia ixx="0.002" ixy="0" ixz="0" iyy="0.002" iyz="0" izz="0.001"/>
    </inertial>
  </link>
  <joint name="robot1_front_right_leg_joint" type="fixed">
    <origin rpy="0 -1.39626344 -1.57079637" xyz="0.282 -0.06 0.090255"/>
    <parent link="robot1_base_link"/>
    <child link="robot1_front_right_leg_joint_link"/>
    <limit effort="500" lower="-3.14159" upper="3.14159" velocity="10"/>
    <dynamics damping="0.005" friction="0.1"/>
    <axis xyz="0 1 0"/>
  </joint>
  <link name="robot1_front_right_leg_joint_link">
    <visual>
      <geometry>
        <mesh filename="package://robot_description/meshes/DAE/leg_joint/leg_joint.dae"/>
      </geometry>
    </visual>
    <collision>
      <geometry>
        <mesh filename="package://robot_description/meshes/STL/leg_joint/leg_joint.stl"/>
      </geometry>
    </collision>
    <inertial>
      <origin xyz="0 0 -0.038"/>
      <mass value="1.16"/>
      <inertia ixx="0.002" ixy="0" ixz="0" iyy="0.002" iyz="0" izz="0.001"/>
    </inertial>
  </link>
  <joint name="robot1_front_left_thigh_joint" type="revolute">
    <origin rpy="1.57079637 0 -2.007128695" xyz="0 0 -0.114"/>
    <parent link="robot1_front_left_leg_joint_link"/>
    <child link="robot1_front_left_thigh_link"/>
    <limit effort="500" lower="-0.785" upper="0.785" velocity="10"/>
    <dynamics damping="0.005" friction="0.1"/>
    <axis xyz="0 1 0"/>
  </joint>
  <link name="robot1_front_left_thigh_link">
    <visual>
      <geometry>
        <mesh filename="package://robot_description/meshes/DAE/left_thigh/left_thigh.dae"/>
      </geometry>
    </visual>
    <collision>
      <geometry>
        <mesh filename="package://robot_description/meshes/STL/left_thigh/left_thigh.stl"/>
      </geometry>
    </collision>
    <inertial>
      <origin xyz="0.17 -0.028 0.014"/>
      <mass value="1.24"/>
      <inertia ixx="0.002" ixy="0" ixz="0" iyy="0.002" iyz="0" izz="0.001"/>
      <!-- inertia ixx="-0.5" ixy="0.003" ixz="0.145" iyy="-0.496" iyz="-0.0096" izz="0.012" -->
    </inertial>
  </link>
  <joint name="robot1_rear_left_thigh_joint" type="fixed">
    <origin rpy="1.57079637 0 -2.356194555" xyz="0 0 -0.114"/>
    <parent link="robot1_rear_left_leg_joint_link"/>
    <child link="robot1_rear_left_thigh_link"/>
    <limit effort="500" lower="-3" upper="3" velocity="10"/>
    <dynamics damping="0.005" friction="0.1"/>
    <axis xyz="0 1 0"/>
  </joint>
  <link name="robot1_rear_left_thigh_link">
    <visual>
      <geometry>
        <mesh filename="package://robot_description/meshes/DAE/left_thigh/left_thigh.dae"/>
      </geometry>
    </visual>
    <collision>
      <geometry>
        <mesh filename="package://robot_description/meshes/STL/left_thigh/left_thigh.stl"/>
      </geometry>
    </collision>
    <inertial>
      <origin xyz="0.17 -0.028 0.014"/>
      <mass value="1.24"/>
      <inertia ixx="0.002" ixy="0" ixz="0" iyy="0.002" iyz="0" izz="0.001"/>
      <!-- inertia ixx="-0.5" ixy="0.003" ixz="0.145" iyy="-0.496" iyz="-0.0096" izz="0.012" -->
    </inertial>
  </link>
  <joint name="robot1_front_right_thigh_joint" type="revolute">
    <origin rpy="1.57079637 0 5.148721435" xyz="0 0 -0.114"/>
    <parent link="robot1_front_right_leg_joint_link"/>
    <child link="robot1_front_right_thigh_link"/>
    <limit effort="500" lower="-0.785" upper="0.785" velocity="10"/>
    <dynamics damping="0.005" friction="0.1"/>
    <axis xyz="0 -1 0"/>
  </joint>
  <link name="robot1_front_right_thigh_link">
    <visual>
      <geometry>
        <mesh filename="package://robot_description/meshes/DAE/right_thigh/right_thigh.dae"/>
      </geometry>
    </visual>
    <collision>
      <geometry>
        <mesh filename="package://robot_description/meshes/STL/right_thigh/right_thigh.stl"/>
      </geometry>
    </collision>
    <inertial>
      <origin xyz="0.17 -0.028 -0.014"/>
      <mass value="1.24"/>
      <inertia ixx="0.002" ixy="0" ixz="0" iyy="0.002" iyz="0" izz="0.001"/>
      <!--inertia ixx="-0.44" ixy="0.012" ixz="0.14" iyy="-0.423" iyz="0.0217" izz="0.0135" -->
    </inertial>
  </link>
  <joint name="robot1_rear_right_thigh_joint" type="fixed">
    <origin rpy="1.57079637 0 5.497787295" xyz="0 0 -0.114"/>
    <parent link="robot1_rear_right_leg_joint_link"/>
    <child link="robot1_rear_right_thigh_link"/>
    <limit effort="500" lower="-3" upper="3" velocity="10"/>
    <dynamics damping="0.005" friction="0.1"/>
    <axis xyz="0 -1 0"/>
  </joint>
  <link name="robot1_rear_right_thigh_link">
    <visual>
      <geometry>
        <mesh filename="package://robot_description/meshes/DAE/right_thigh/right_thigh.dae"/>
      </geometry>
    </visual>
    <collision>
      <geometry>
        <mesh filename="package://robot_description/meshes/STL/right_thigh/right_thigh.stl"/>
      </geometry>
    </collision>
    <inertial>
      <origin xyz="0.17 -0.028 -0.014"/>
      <mass value="1.24"/>
      <inertia ixx="0.002" ixy="0" ixz="0" iyy="0.002" iyz="0" izz="0.001"/>
      <!--inertia ixx="-0.44" ixy="0.012" ixz="0.14" iyy="-0.423" iyz="0.0217" izz="0.0135" -->
    </inertial>
  </link>
  <joint name="robot1_front_left_shin_joint" type="fixed">
    <origin rpy="0 -1.04719758 0" xyz="0.426 -0.0285 0"/>
    <parent link="robot1_front_left_thigh_link"/>
    <child link="robot1_front_left_shin_link"/>
    <limit effort="500" lower="-3.14159" upper="3.14159" velocity="10"/>
    <dynamics damping="0.005" friction="0.1"/>
    <axis xyz="0 1 0"/>
  </joint>
  <link name="robot1_front_left_shin_link">
    <visual>
      <geometry>
        <mesh filename="package://robot_description/meshes/DAE/shin/shin.dae"/>
      </geometry>
    </visual>
    <collision>
      <geometry>
        <mesh filename="package://robot_description/meshes/STL/shin/shin.stl"/>
      </geometry>
    </collision>
    <inertial>
      <origin xyz="-0.158 0.011 0.0"/>
      <mass value="0.66"/>
      <inertia ixx="0.0003" ixy="0.0013" ixz="0.000045" iyy="0.029" iyz="-0.000003" izz="0.029"/>
    </inertial>
    <surface>
      <friction>
        <ode>
          <mu1>1.2</mu1>
          <mu2>1.2</mu2>
          <kp>1e15</kp>
          <kd>1e13</kd>
        </ode>
      </friction>
      <bounce>
        <restitution_coefficient>0.01</restitution_coefficient>
        <threshold>0</threshold>
      </bounce>
      <contact>
        <ode>
          <max_vel>10</max_vel>
        </ode>
      </contact>
    </surface>
  </link>
  <joint name="robot1_front_right_shin_joint" type="fixed">
    <origin rpy="3.14159274 1.04719758 0" xyz="0.426 -0.0285 0"/>
    <parent link="robot1_front_right_thigh_link"/>
    <child link="robot1_front_right_shin_link"/>
    <limit effort="500" lower="-3.14159" upper="3.14159" velocity="10"/>
    <dynamics damping="0.005" friction="0.1"/>
    <axis xyz="0 1 0"/>
  </joint>
  <link name="robot1_front_right_shin_link">
    <visual>
      <geometry>
        <mesh filename="package://robot_description/meshes/DAE/shin/shin.dae"/>
      </geometry>
    </visual>
    <collision>
      <geometry>
        <mesh filename="package://robot_description/meshes/STL/shin/shin.stl"/>
      </geometry>
    </collision>
    <inertial>
      <origin xyz="-0.158 0.011 0.0"/>
      <mass value="0.66"/>
      <inertia ixx="0.0003" ixy="0.0013" ixz="0.000045" iyy="0.029" iyz="-0.000003" izz="0.029"/>
    </inertial>
    <surface>
      <friction>
        <ode>
          <mu1>1.2</mu1>
          <mu2>1.2</mu2>
          <kp>1e15</kp>
          <kd>1e13</kd>
        </ode>
      </friction>
      <bounce>
        <restitution_coefficient>0.01</restitution_coefficient>
        <threshold>0</threshold>
      </bounce>
      <contact>
        <ode>
          <max_vel>10</max_vel>
        </ode>
      </contact>
    </surface>
  </link>
  <joint name="robot1_rear_left_shin_joint" type="fixed">
    <origin rpy="0 -1.2217305100000002 0" xyz="0.426 -0.0285 0"/>
    <parent link="robot1_rear_left_thigh_link"/>
    <child link="robot1_rear_left_shin_link"/>
    <limit effort="500" lower="-3.14159" upper="3.14159" velocity="10"/>
    <dynamics damping="0.005" friction="0.1"/>
    <axis xyz="0 1 0"/>
  </joint>
  <link name="robot1_rear_left_shin_link">
    <visual>
      <geometry>
        <mesh filename="package://robot_description/meshes/DAE/shin/shin.dae"/>
      </geometry>
    </visual>
    <collision>
      <geometry>
        <mesh filename="package://robot_description/meshes/STL/shin/shin.stl"/>
      </geometry>
    </collision>
    <inertial>
      <origin xyz="-0.158 0.011 0.0"/>
      <mass value="0.66"/>
      <inertia ixx="0.0003" ixy="0.0013" ixz="0.000045" iyy="0.029" iyz="-0.000003" izz="0.029"/>
    </inertial>
    <surface>
      <friction>
        <ode>
          <mu1>1.2</mu1>
          <mu2>1.2</mu2>
          <kp>1e15</kp>
          <kd>1e13</kd>
        </ode>
      </friction>
      <bounce>
        <restitution_coefficient>0.01</restitution_coefficient>
        <threshold>0</threshold>
      </bounce>
      <contact>
        <ode>
          <max_vel>10</max_vel>
        </ode>
      </contact>
    </surface>
  </link>
  <joint name="robot1_rear_right_shin_joint" type="fixed">
    <origin rpy="3.14159274 1.2217305100000002 0" xyz="0.426 -0.0285 0"/>
    <parent link="robot1_rear_right_thigh_link"/>
    <child link="robot1_rear_right_shin_link"/>
    <limit effort="500" lower="-3.14159" upper="3.14159" velocity="10"/>
    <dynamics damping="0.005" friction="0.1"/>
    <axis xyz="0 1 0"/>
  </joint>
  <link name="robot1_rear_right_shin_link">
    <visual>
      <geometry>
        <mesh filename="package://robot_description/meshes/DAE/shin/shin.dae"/>
      </geometry>
    </visual>
    <collision>
      <geometry>
        <mesh filename="package://robot_description/meshes/STL/shin/shin.stl"/>
      </geometry>
    </collision>
    <inertial>
      <origin xyz="-0.158 0.011 0.0"/>
      <mass value="0.66"/>
      <inertia ixx="0.0003" ixy="0.0013" ixz="0.000045" iyy="0.029" iyz="-0.000003" izz="0.029"/>
    </inertial>
    <surface>
      <friction>
        <ode>
          <mu1>1.2</mu1>
          <mu2>1.2</mu2>
          <kp>1e15</kp>
          <kd>1e13</kd>
        </ode>
      </friction>
      <bounce>
        <restitution_coefficient>0.01</restitution_coefficient>
        <threshold>0</threshold>
      </bounce>
      <contact>
        <ode>
          <max_vel>10</max_vel>
        </ode>
      </contact>
    </surface>
  </link>
  <joint name="robot1_fr_wheel_joint" type="fixed">
    <origin rpy="0 0 0" xyz="-0.345 0.0165 0.0"/>
    <parent link="robot1_front_right_shin_link"/>
    <child link="robot1_fr_wheel_link"/>
    <limit effort="100" velocity="100"/>
    <axis xyz="0 -1 0"/>
  </joint>
  <link name="robot1_fr_wheel_link">
    <visual>
      <geometry>
        <mesh filename="package://robot_description/meshes/DAE/wheel/wheel.dae"/>
      </geometry>
    </visual>
    <collision>
      <geometry>
        <mesh filename="package://robot_description/meshes/STL/wheel/wheel.stl"/>
      </geometry>
    </collision>
    <inertial>
      <origin xyz="0.0 0.01 0.0"/>
      <mass value="0.64"/>
      <inertia ixx="0.001647" ixy="0" ixz="0" iyy="0.00325" iyz="0" izz="0.001647"/>
    </inertial>
    <surface>
      <friction>
        <ode>
          <mu1>1.2</mu1>
          <mu2>1.2</mu2>
          <kp>1e15</kp>
          <kd>1e13</kd>
        </ode>
      </friction>
      <bounce>
        <restitution_coefficient>0.01</restitution_coefficient>
        <threshold>0</threshold>
      </bounce>
      <contact>
        <ode>
          <max_vel>10</max_vel>
        </ode>
      </contact>
    </surface>
  </link>
  <joint name="robot1_fl_wheel_joint" type="fixed">
    <origin rpy="0 0 3.14159274" xyz="-0.345 -0.0165 0.0"/>
    <parent link="robot1_front_left_shin_link"/>
    <child link="robot1_fl_wheel_link"/>
    <limit effort="100" velocity="100"/>
    <axis xyz="0 1 0"/>
  </joint>
  <link name="robot1_fl_wheel_link">
    <visual>
      <geometry>
        <mesh filename="package://robot_description/meshes/DAE/wheel/wheel.dae"/>
      </geometry>
    </visual>
    <collision>
      <geometry>
        <mesh filename="package://robot_description/meshes/STL/wheel/wheel.stl"/>
      </geometry>
    </collision>
    <inertial>
      <origin xyz="0.0 0.01 0.0"/>
      <mass value="0.64"/>
      <inertia ixx="0.001647" ixy="0" ixz="0" iyy="0.00325" iyz="0" izz="0.001647"/>
    </inertial>
    <surface>
      <friction>
        <ode>
          <mu1>1.2</mu1>
          <mu2>1.2</mu2>
          <kp>1e15</kp>
          <kd>1e13</kd>
        </ode>
      </friction>
      <bounce>
        <restitution_coefficient>0.01</restitution_coefficient>
        <threshold>0</threshold>
      </bounce>
      <contact>
        <ode>
          <max_vel>10</max_vel>
        </ode>
      </contact>
    </surface>
  </link>
  <joint name="robot1_rl_wheel_joint" type="continuous">
    <origin rpy="0 0 3.14159274" xyz="-0.345 -0.0165 0.0"/>
    <parent link="robot1_rear_left_shin_link"/>
    <child link="robot1_rl_wheel_link"/>
    <limit effort="100" velocity="100"/>
    <axis xyz="0 1 0"/>
  </joint>
  <link name="robot1_rl_wheel_link">
    <visual>
      <geometry>
        <mesh filename="package://robot_description/meshes/DAE/wheel/wheel.dae"/>
      </geometry>
    </visual>
    <collision>
      <geometry>
        <mesh filename="package://robot_description/meshes/STL/wheel/wheel.stl"/>
      </geometry>
    </collision>
    <inertial>
      <origin xyz="0.0 0.01 0.0"/>
      <mass value="0.64"/>
      <inertia ixx="0.001647" ixy="0" ixz="0" iyy="0.00325" iyz="0" izz="0.001647"/>
    </inertial>
    <surface>
      <friction>
        <ode>
          <mu1>1.2</mu1>
          <mu2>1.2</mu2>
          <kp>1e15</kp>
          <kd>1e13</kd>
        </ode>
      </friction>
      <bounce>
        <restitution_coefficient>0.01</restitution_coefficient>
        <threshold>0</threshold>
      </bounce>
      <contact>
        <ode>
          <max_vel>10</max_vel>
        </ode>
      </contact>
    </surface>
  </link>
  <joint name="robot1_rr_wheel_joint" type="continuous">
    <origin rpy="0 0 0" xyz="-0.345 0.0165 0.0"/>
    <parent link="robot1_rear_right_shin_link"/>
    <child link="robot1_rr_wheel_link"/>
    <limit effort="100" velocity="100"/>
    <axis xyz="0 -1 0"/>
  </joint>
  <link name="robot1_rr_wheel_link">
    <visual>
      <geometry>
        <mesh filename="package://robot_description/meshes/DAE/wheel/wheel.dae"/>
      </geometry>
    </visual>
    <collision>
      <geometry>
        <mesh filename="package://robot_description/meshes/STL/wheel/wheel.stl"/>
      </geometry>
    </collision>
    <inertial>
      <origin xyz="0.0 0.01 0.0"/>
      <mass value="0.64"/>
      <inertia ixx="0.001647" ixy="0" ixz="0" iyy="0.00325" iyz="0" izz="0.001647"/>
    </inertial>
    <surface>
      <friction>
        <ode>
          <mu1>1.2</mu1>
          <mu2>1.2</mu2>
          <kp>1e15</kp>
          <kd>1e13</kd>
        </ode>
      </friction>
      <bounce>
        <restitution_coefficient>0.01</restitution_coefficient>
        <threshold>0</threshold>
      </bounce>
      <contact>
        <ode>
          <max_vel>10</max_vel>
        </ode>
      </contact>
    </surface>
  </link>
</robot>
